<?xml version="1.0" encoding="utf-8"?>
<robot name="panda_hand">
  <joint name="panda_hand_joint" type="fixed">
    <parent link="panda_link8"/>
    <child link="panda_hand"/>
    <origin rpy="0 0 -0.7853981633974483" xyz="0 0 0"/>
  </joint>
  <link name="panda_hand">
    <inertial>
      <mass value="0.73"/>
      <origin xyz="-0.01 0 0.03"/>
      <inertia ixx="0.001" ixy="0" ixz="0" iyy="0.0025" iyz="0" izz="0.0017"/>
    </inertial>
    <visual>
      <geometry>
        <mesh filename="file://@MODULE_INSTALL_LOCATION@/meshes/panda_hand/hand.dae"/>
      </geometry>
    </visual>
    <collision>
      <origin rpy="0 1.5707963267948966 1.5707963267948966" xyz="0 0 0.04"/>
      <geometry>
        <cylinder length="0.1" radius="0.04"/>
      </geometry>
    </collision>
    <collision>
      <origin rpy="0 0 0" xyz="0 -0.05 0.04"/>
      <geometry>
        <sphere radius="0.04"/>
      </geometry>
    </collision>
    <collision>
      <origin rpy="0 0 0" xyz="0 0.05 0.04"/>
      <geometry>
        <sphere radius="0.04"/>
      </geometry>
    </collision>
    <collision>
      <origin rpy="0 1.5707963267948966 1.5707963267948966" xyz="0 0 0.1"/>
      <geometry>
        <cylinder length="0.1" radius="0.02"/>
      </geometry>
    </collision>
    <collision>
      <origin rpy="0 0 0" xyz="0 -0.05 0.1"/>
      <geometry>
        <sphere radius="0.02"/>
      </geometry>
    </collision>
    <collision>
      <origin rpy="0 0 0" xyz="0 0.05 0.1"/>
      <geometry>
        <sphere radius="0.02"/>
      </geometry>
    </collision>
  </link>
  <link name="panda_leftfinger">
    <visual>
      <geometry>
        <mesh filename="file://@MODULE_INSTALL_LOCATION@/meshes/panda_hand/finger.dae"/>
      </geometry>
    </visual>
  </link>
  <link name="panda_rightfinger">
    <visual>
      <origin rpy="0 0 3.141592653589793" xyz="0 0 0"/>
      <geometry>
        <mesh filename="file://@MODULE_INSTALL_LOCATION@/meshes/panda_hand/finger.dae"/>
      </geometry>
    </visual>
  </link>
  <joint name="panda_finger_joint1" type="prismatic">
    <parent link="panda_hand"/>
    <child link="panda_leftfinger"/>
    <origin rpy="0 0 0" xyz="0 0 0.0584"/>
    <axis xyz="0 1 0"/>
    <limit effort="20" lower="0.0" upper="0.04" velocity="0.2"/>
  </joint>
  <joint name="panda_finger_joint2" type="prismatic">
    <parent link="panda_hand"/>
    <child link="panda_rightfinger"/>
    <origin rpy="0 0 0" xyz="0 0 0.0584"/>
    <axis xyz="0 -1 0"/>
    <limit effort="20" lower="0.0" upper="0.04" velocity="0.2"/>
    <mimic joint="panda_finger_joint1"/>
  </joint>
</robot>
