<?xml version="1.0" ?>
<!-- =================================================================================== -->
<!-- |    This document was autogenerated by xacro from /workspaces/src/franka_description/robots/fr3/fr3.urdf.xacro | -->
<!-- |    EDITING THIS FILE BY HAND IS NOT RECOMMENDED                                 | -->
<!-- =================================================================================== -->
<robot name="fr3">
  <!-- safety_distance: Minimum safety distance in [m] by which the collision volumes are expanded and which is enforced during robot motions -->
  <!-- robot_type: Namespace of the robot arm. Serves to differentiate between arms in case of multiple instances. -->
  <!-- joint_limits: description of the joint limits that comes from a YAML file. Example definition: ${xacro.load_yaml('$(find franka_description)/robots/fr3/joint_limits.yaml')} -->
  <!-- kinematics: description of the kinematics that comes from a YAML file. Example definition: ${xacro.load_yaml('$(find franka_description)/robots/fr3/kinematics.yaml')} -->
  <!-- inertials: description of the inertials that comes from a YAML file. Example definition: ${xacro.load_yaml('$(find franka_description)/robots/fr3/inertials.yaml')} -->
  <!-- dynamics: description of the dynamics that comes from a YAML file. Example definition: ${xacro.load_yaml('$(find franka_description)/robots/fr3/dynamics.yaml')} -->
  <link name="base">
      </link>
  <joint name="panda_base_joint" type="fixed">
    <parent link="base"/>
    <child link="panda_link0"/>
    <origin rpy="0 0 0" xyz="0 0 0"/>
  </joint>
  <!-- sub-link defining detailed meshes for collision with environment -->
  <link name="panda_link0">
    <visual name="panda_link0_visual">
      <geometry>
        <mesh filename="file://@FR3_DESCRIPTION_PATH@/meshes/visual/link0.dae"/>
      </geometry>
    </visual>
    <collision name="panda_link0_collision">
      <geometry>
        <mesh filename="file://@FR3_DESCRIPTION_PATH@/meshes/collision/link0.stl"/>
      </geometry>
    </collision>
    <inertial>
      <origin rpy="0 0 0" xyz="-0.0172 0.0004 0.0745"/>
      <mass value="2.3966"/>
      <inertia ixx="0.009" ixy="0.0" ixz="0.002" iyy="0.0115" iyz="0.0" izz="0.0085"/>
    </inertial>
  </link>
  <link name="panda_link0_accelerometer_top">
      </link>
  <joint name="panda_link0_accelerometer_top_joint" type="fixed">
    <origin rpy="3.1416 0.0 0.0" xyz="-0.017402 -0.007872 0.04715"/>
    <parent link="panda_link0"/>
    <child link="panda_link0_accelerometer_top"/>
  </joint>
  <link name="panda_link0_accelerometer_bottom">
      </link>
  <joint name="panda_link0_accelerometer_bottom_joint" type="fixed">
    <origin rpy="0.0 0.0 -1.5708" xyz="-0.019739 0.0015506 0.05075"/>
    <parent link="panda_link0"/>
    <child link="panda_link0_accelerometer_bottom"/>
  </joint>
  <!-- sub-link defining detailed meshes for collision with environment -->
  <link name="panda_link1">
    <visual name="panda_link1_visual">
      <geometry>
        <mesh filename="file://@FR3_DESCRIPTION_PATH@/meshes/visual/link1.dae"/>
      </geometry>
    </visual>
    <collision name="panda_link1_collision">
      <geometry>
        <mesh filename="file://@FR3_DESCRIPTION_PATH@/meshes/collision/link1.stl"/>
      </geometry>
    </collision>
    <inertial>
      <origin rpy="0 0 0" xyz="0.0000004128 -0.0181251324 -0.0386035970"/>
      <mass value="2.9274653454"/>
      <inertia ixx="0.023927316485107913" ixy="1.3317903455714081e-05" ixz="-0.00011404774918616684" iyy="0.0224821613275756" iyz="-0.0019950320628240115" izz="0.006350098258530016"/>
    </inertial>
  </link>
  <link name="panda_link1_accelerometer_top">
      </link>
  <joint name="panda_link1_accelerometer_top_joint" type="fixed">
    <origin rpy="-1.5708 0.0 3.1416" xyz="0.017402 -0.093352 -0.00787"/>
    <parent link="panda_link1"/>
    <child link="panda_link1_accelerometer_top"/>
  </joint>
  <link name="panda_link1_accelerometer_bottom">
      </link>
  <joint name="panda_link1_accelerometer_bottom_joint" type="fixed">
    <origin rpy="-1.5708 1.5708 0.0" xyz="0.01974 -0.08975 0.00155"/>
    <parent link="panda_link1"/>
    <child link="panda_link1_accelerometer_bottom"/>
  </joint>
  <joint name="panda_joint1" type="revolute">
    <origin rpy="0 0 0" xyz="0 0 0.333"/>
    <parent link="panda_link0"/>
    <child link="panda_link1"/>
    <axis xyz="0 0 1"/>
    <limit effort="87.0" lower="-2.9007" upper="2.9007" velocity="2.62"/>
    <safety_controller k_position="100.0" k_velocity="40.0" soft_lower_limit="-2.9007" soft_upper_limit="2.9007"/>
    <position_based_velocity_limits deceleration_limit="6.0" velocity_offset="0.652"/>
    <dynamics D="1" K="7000" damping="0.003" friction="0.2" gear_ratio="120.0" motor_inertia="4.206399e-05" mu_coulomb="0" mu_viscous="16"/>
  </joint>
  <!-- sub-link defining detailed meshes for collision with environment -->
  <link name="panda_link2">
    <visual name="panda_link2_visual">
      <geometry>
        <mesh filename="file://@FR3_DESCRIPTION_PATH@/meshes/visual/link2.dae"/>
      </geometry>
    </visual>
    <collision name="panda_link2_collision">
      <geometry>
        <mesh filename="file://@FR3_DESCRIPTION_PATH@/meshes/collision/link2.stl"/>
      </geometry>
    </collision>
    <inertial>
      <origin rpy="0 0 0" xyz="0.0031828864 -0.0743221644 0.0088146084"/>
      <mass value="2.9355370338"/>
      <inertia ixx="0.041938946257609425" ixy="0.00020257331521090626" ixz="0.004077784227179924" iyy="0.02514514885014724" iyz="-0.0042252158006570156" izz="0.06170214472888839"/>
    </inertial>
  </link>
  <link name="panda_link2_accelerometer_top">
      </link>
  <joint name="panda_link2_accelerometer_top_joint" type="fixed">
    <origin rpy="1.5708 0.0 3.1416" xyz="0.017403 -0.11715 0.00787"/>
    <parent link="panda_link2"/>
    <child link="panda_link2_accelerometer_top"/>
  </joint>
  <link name="panda_link2_accelerometer_bottom">
      </link>
  <joint name="panda_link2_accelerometer_bottom_joint" type="fixed">
    <origin rpy="1.5708 -1.5708 0.0" xyz="0.019737 -0.11875 -0.00155"/>
    <parent link="panda_link2"/>
    <child link="panda_link2_accelerometer_bottom"/>
  </joint>
  <joint name="panda_joint2" type="revolute">
    <origin rpy="-1.570796326794897 0 0" xyz="0 0 0"/>
    <parent link="panda_link1"/>
    <child link="panda_link2"/>
    <axis xyz="0 0 1"/>
    <limit effort="87.0" lower="-1.8361" upper="1.8361" velocity="2.62"/>
    <safety_controller k_position="100.0" k_velocity="40.0" soft_lower_limit="-1.8361" soft_upper_limit="1.8361"/>
    <position_based_velocity_limits deceleration_limit="2.585" velocity_offset="0.25"/>
    <dynamics D="1" K="7000" damping="0.003" friction="0.2" gear_ratio="120.0" motor_inertia="4.206399e-05" mu_coulomb="0" mu_viscous="16"/>
  </joint>
  <!-- sub-link defining detailed meshes for collision with environment -->
  <link name="panda_link3">
    <visual name="panda_link3_visual">
      <geometry>
        <mesh filename="file://@FR3_DESCRIPTION_PATH@/meshes/visual/link3.dae"/>
      </geometry>
    </visual>
    <collision name="panda_link3_collision">
      <geometry>
        <mesh filename="file://@FR3_DESCRIPTION_PATH@/meshes/collision/link3.stl"/>
      </geometry>
    </collision>
    <inertial>
      <origin rpy="0 0 0" xyz="0.0407015686 -0.0048200565 -0.0289730823"/>
      <mass value="2.2449013699"/>
      <inertia ixx="0.02410142547240885" ixy="0.002404694559042109" ixz="-0.002856269270114313" iyy="0.01974053266708178" iyz="-0.002104212683891874" izz="0.019044494482244823"/>
    </inertial>
  </link>
  <link name="panda_link3_accelerometer_top">
      </link>
  <joint name="panda_link3_accelerometer_top_joint" type="fixed">
    <origin rpy="-1.5708 0.0 0.0" xyz="0.065099 0.077352 -0.00787"/>
    <parent link="panda_link3"/>
    <child link="panda_link3_accelerometer_top"/>
  </joint>
  <link name="panda_link3_accelerometer_bottom">
      </link>
  <joint name="panda_link3_accelerometer_bottom_joint" type="fixed">
    <origin rpy="1.5708 1.5708 0.0" xyz="0.062769 0.073756 0.00155"/>
    <parent link="panda_link3"/>
    <child link="panda_link3_accelerometer_bottom"/>
  </joint>
  <joint name="panda_joint3" type="revolute">
    <origin rpy="1.570796326794897 0 0" xyz="0 -0.316 0"/>
    <parent link="panda_link2"/>
    <child link="panda_link3"/>
    <axis xyz="0 0 1"/>
    <limit effort="87.0" lower="-2.9007" upper="2.9007" velocity="2.62"/>
    <safety_controller k_position="100.0" k_velocity="40.0" soft_lower_limit="-2.9007" soft_upper_limit="2.9007"/>
    <position_based_velocity_limits deceleration_limit="3.5" velocity_offset="0.2005"/>
    <dynamics D="1" K="7000" damping="0.003" friction="0.2" gear_ratio="120.0" motor_inertia="3.211626e-05" mu_coulomb="0" mu_viscous="16"/>
  </joint>
  <!-- sub-link defining detailed meshes for collision with environment -->
  <link name="panda_link4">
    <visual name="panda_link4_visual">
      <geometry>
        <mesh filename="file://@FR3_DESCRIPTION_PATH@/meshes/visual/link4.dae"/>
      </geometry>
    </visual>
    <collision name="panda_link4_collision">
      <geometry>
        <mesh filename="file://@FR3_DESCRIPTION_PATH@/meshes/collision/link4.stl"/>
      </geometry>
    </collision>
    <inertial>
      <origin rpy="0 0 0" xyz="-0.0459100965 0.0630492960 -0.0085187868"/>
      <mass value="2.6155955791"/>
      <inertia ixx="0.03452998321913202" ixy="0.01322552265982813" ixz="0.01015142998484113" iyy="0.028881621933049058" iyz="-0.0009762833870704552" izz="0.04125471171146641"/>
    </inertial>
  </link>
  <link name="panda_link4_accelerometer_top">
      </link>
  <joint name="panda_link4_accelerometer_top_joint" type="fixed">
    <origin rpy="-1.5708 0.0 -3.1416" xyz="-0.0651 0.046252 -0.00787"/>
    <parent link="panda_link4"/>
    <child link="panda_link4_accelerometer_top"/>
  </joint>
  <link name="panda_link4_accelerometer_bottom">
      </link>
  <joint name="panda_link4_accelerometer_bottom_joint" type="fixed">
    <origin rpy="-1.5708 1.5708 0.0" xyz="-0.062775 0.049753 0.00155"/>
    <parent link="panda_link4"/>
    <child link="panda_link4_accelerometer_bottom"/>
  </joint>
  <joint name="panda_joint4" type="revolute">
    <origin rpy="1.570796326794897 0 0" xyz="0.0825 0 0"/>
    <parent link="panda_link3"/>
    <child link="panda_link4"/>
    <axis xyz="0 0 1"/>
    <limit effort="87.0" lower="-3.077" upper="-0.1169" velocity="2.62"/>
    <safety_controller k_position="100.0" k_velocity="40.0" soft_lower_limit="-3.077" soft_upper_limit="-0.1169"/>
    <position_based_velocity_limits deceleration_limit="4.0" velocity_offset="0.3542"/>
    <dynamics D="1" K="7000" damping="0.003" friction="0.2" gear_ratio="120.0" motor_inertia="3.211626e-05" mu_coulomb="0" mu_viscous="16"/>
  </joint>
  <!-- sub-link defining detailed meshes for collision with environment -->
  <link name="panda_link5">
    <visual name="panda_link5_visual">
      <geometry>
        <mesh filename="file://@FR3_DESCRIPTION_PATH@/meshes/visual/link5.dae"/>
      </geometry>
    </visual>
    <collision name="panda_link5_collision">
      <geometry>
        <mesh filename="file://@FR3_DESCRIPTION_PATH@/meshes/collision/link5.stl"/>
      </geometry>
    </collision>
    <inertial>
      <origin rpy="0 0 0" xyz="-0.0016039605 0.0292536262 -0.0972965990"/>
      <mass value="2.3271207594"/>
      <inertia ixx="0.051610278463662895" ixy="-0.005715173387783472" ixz="-0.0035673167625872135" iyy="0.04787729713371481" iyz="0.010673985108535986" izz="0.016423625579357254"/>
    </inertial>
  </link>
  <link name="panda_link5_accelerometer_top">
      </link>
  <joint name="panda_link5_accelerometer_top_joint" type="fixed">
    <origin rpy="-1.5708 0.0 0.0" xyz="-0.017363 0.085872 -0.00795"/>
    <parent link="panda_link5"/>
    <child link="panda_link5_accelerometer_top"/>
  </joint>
  <link name="panda_link5_accelerometer_bottom">
      </link>
  <joint name="panda_link5_accelerometer_bottom_joint" type="fixed">
    <origin rpy="1.5708 1.5708 0.0" xyz="-0.019742 0.082275 0.00146"/>
    <parent link="panda_link5"/>
    <child link="panda_link5_accelerometer_bottom"/>
  </joint>
  <joint name="panda_joint5" type="revolute">
    <origin rpy="-1.570796326794897 0 0" xyz="-0.0825 0.384 0"/>
    <parent link="panda_link4"/>
    <child link="panda_link5"/>
    <axis xyz="0 0 1"/>
    <limit effort="12.0" lower="-2.8763" upper="2.8763" velocity="5.26"/>
    <safety_controller k_position="100.0" k_velocity="40.0" soft_lower_limit="-2.8763" soft_upper_limit="2.8763"/>
    <position_based_velocity_limits deceleration_limit="17.0" velocity_offset="0.5738"/>
    <dynamics D="1" K="7000" damping="0.003" friction="0.2" gear_ratio="80.0" motor_inertia="3.211626e-05" mu_coulomb="0" mu_viscous="16"/>
  </joint>
  <!-- sub-link defining detailed meshes for collision with environment -->
  <link name="panda_link6">
    <visual name="panda_link6_visual">
      <geometry>
        <mesh filename="file://@FR3_DESCRIPTION_PATH@/meshes/visual/link6.dae"/>
      </geometry>
    </visual>
    <collision name="panda_link6_collision">
      <geometry>
        <mesh filename="file://@FR3_DESCRIPTION_PATH@/meshes/collision/link6.stl"/>
      </geometry>
    </collision>
    <inertial>
      <origin rpy="0 0 0" xyz="0.0597131221 -0.0410294666 -0.0101692726"/>
      <mass value="1.8170376524"/>
      <inertia ixx="0.005412333594383447" ixy="0.006193456360285834" ixz="0.0014219289306117652" iyy="0.014058329545509979" iyz="-0.0013140753741120031" izz="0.016080817924212554"/>
    </inertial>
  </link>
  <joint name="panda_joint6" type="revolute">
    <origin rpy="1.570796326794897 0 0" xyz="0 0 0"/>
    <parent link="panda_link5"/>
    <child link="panda_link6"/>
    <axis xyz="0 0 1"/>
    <limit effort="12.0" lower="0.4398" upper="4.6216" velocity="4.18"/>
    <safety_controller k_position="100.0" k_velocity="40.0" soft_lower_limit="0.4398" soft_upper_limit="4.6216"/>
    <position_based_velocity_limits deceleration_limit="5.5" velocity_offset="0.4885"/>
    <dynamics D="1" K="7000" damping="0.003" friction="0.2" gear_ratio="80.0" motor_inertia="3.211626e-05" mu_coulomb="0" mu_viscous="16"/>
  </joint>
  <!-- sub-link defining detailed meshes for collision with environment -->
  <link name="panda_link7">
    <visual name="panda_link7_visual">
      <geometry>
        <mesh filename="file://@FR3_DESCRIPTION_PATH@/meshes/visual/link7.dae"/>
      </geometry>
    </visual>
    <collision name="panda_link7_collision">
      <geometry>
        <mesh filename="file://@FR3_DESCRIPTION_PATH@/meshes/collision/link7.stl"/>
      </geometry>
    </collision>
    <inertial>
      <origin rpy="0 0 0" xyz="0.0045225817 0.0086261921 -0.0161633251"/>
      <mass value="0.6271432862"/>
      <inertia ixx="0.00021092389150104718" ixy="-2.433299114461931e-05" ixz="4.564480393778983e-05" iyy="0.00017718568002411474" iyz="8.744070223226438e-05" izz="5.993190599659971e-05"/>
    </inertial>
  </link>
  <joint name="panda_joint7" type="revolute">
    <origin rpy="1.570796326794897 0 0" xyz="0.088 0 0"/>
    <parent link="panda_link6"/>
    <child link="panda_link7"/>
    <axis xyz="0 0 1"/>
    <limit effort="12.0" lower="-3.0508" upper="3.0508" velocity="5.26"/>
    <safety_controller k_position="100.0" k_velocity="40.0" soft_lower_limit="-3.0508" soft_upper_limit="3.0508"/>fr3.
    <position_based_velocity_limits deceleration_limit="17.0" velocity_offset="0.4592"/>
    <dynamics D="1" K="7000" damping="0.003" friction="0.2" gear_ratio="80.0" motor_inertia="3.211626e-05" mu_coulomb="0" mu_viscous="16"/>
  </joint>
  <link name="panda_link8"/>
  <joint name="panda_joint8" type="fixed">
    <origin rpy="0 0 0" xyz="0 0 0.107"/>
    <parent link="panda_link7"/>
    <child link="panda_link8"/>
  </joint>
</robot>
